# 9.6.1

다음 프로그램의 실행 결과를 보이시오

```java
class Ex extends Exception{}
public class ExerciseCh9_6_1 {
    public static void main(String[] args){
        System.out.println("Entering first try block");
        try{
            System.out.println("Entering second try block");
            try{
                throw new Ex();
            }finally{
                System.out.println("finally in 2nd try block");
            }
        }catch (Ex e){
            System.out.println("Caught Ex in first try block");
        }finally{
            System.out.println("finally in 1st try block");
        }
    }
}

```

### [**Solution**](../Solutions/9.6.1.md)

___

### [**Back to the List**](../#list-of-problems)
